[2022-02-28 14:31:54,434] [views.py:80] [views:get_context] [ERROR]- 身份错误
